Watching for file changes with StatReloader
Performing system checks...

System check identified no issues (0 silenced).

You have 18 unapplied migration(s). Your project may not work properly until you apply the migrations for app(s): admin, auth, contenttypes, sessions.
Run 'python manage.py migrate' to apply them.
April 13, 2024 - 13:12:45
Django version 4.2.11, using settings 'config.settings'
Starting development server at http://0.0.0.0:8080/
Quit the server with CONTROL-C.

Invalid HTTP_HOST header: '118.67.131.36:8080'. You may need to add '118.67.131.36' to ALLOWED_HOSTS.
Traceback (most recent call last):
  File "/usr/local/lib/python3.8/dist-packages/django/core/handlers/exception.py", line 55, in inner
    response = get_response(request)
  File "/usr/local/lib/python3.8/dist-packages/django/utils/deprecation.py", line 133, in __call__
    response = self.process_request(request)
  File "/usr/local/lib/python3.8/dist-packages/django/middleware/common.py", line 48, in process_request
    host = request.get_host()
  File "/usr/local/lib/python3.8/dist-packages/django/http/request.py", line 150, in get_host
    raise DisallowedHost(msg)
django.core.exceptions.DisallowedHost: Invalid HTTP_HOST header: '118.67.131.36:8080'. You may need to add '118.67.131.36' to ALLOWED_HOSTS.
Bad Request: /
[13/Apr/2024 13:12:55] "GET / HTTP/1.1" 400 63206
Invalid HTTP_HOST header: '118.67.131.36:8080'. You may need to add '118.67.131.36' to ALLOWED_HOSTS.
Traceback (most recent call last):
  File "/usr/local/lib/python3.8/dist-packages/django/core/handlers/exception.py", line 55, in inner
    response = get_response(request)
  File "/usr/local/lib/python3.8/dist-packages/django/utils/deprecation.py", line 133, in __call__
    response = self.process_request(request)
  File "/usr/local/lib/python3.8/dist-packages/django/middleware/common.py", line 48, in process_request
    host = request.get_host()
  File "/usr/local/lib/python3.8/dist-packages/django/http/request.py", line 150, in get_host
    raise DisallowedHost(msg)
django.core.exceptions.DisallowedHost: Invalid HTTP_HOST header: '118.67.131.36:8080'. You may need to add '118.67.131.36' to ALLOWED_HOSTS.
Bad Request: /favicon.ico
[13/Apr/2024 13:12:55] "GET /favicon.ico HTTP/1.1" 400 63263
/root/mysite/config/settings.py changed, reloading.
Watching for file changes with StatReloader
Performing system checks...

System check identified no issues (0 silenced).

You have 18 unapplied migration(s). Your project may not work properly until you apply the migrations for app(s): admin, auth, contenttypes, sessions.
Run 'python manage.py migrate' to apply them.
April 13, 2024 - 13:13:15
Django version 4.2.11, using settings 'config.settings'
Starting development server at http://0.0.0.0:8080/
Quit the server with CONTROL-C.

Not Found: /
[13/Apr/2024 13:13:16] "GET / HTTP/1.1" 404 2168
Not Found: /favicon.ico
[13/Apr/2024 13:13:16] "GET /favicon.ico HTTP/1.1" 404 2219
Not Found: /
[13/Apr/2024 13:13:17] "GET / HTTP/1.1" 404 2168
Not Found: /
[13/Apr/2024 13:13:17] "GET / HTTP/1.1" 404 2168
Not Found: /
[13/Apr/2024 13:13:17] "GET / HTTP/1.1" 404 2168
Not Found: /
[13/Apr/2024 13:13:18] "GET / HTTP/1.1" 404 2168
Not Found: /
[13/Apr/2024 13:13:18] "GET / HTTP/1.1" 404 2168
Not Found: /
[13/Apr/2024 13:13:18] "GET / HTTP/1.1" 404 2168
/root/mysite/config/urls.py changed, reloading.
Watching for file changes with StatReloader
Performing system checks...

System check identified no issues (0 silenced).

You have 18 unapplied migration(s). Your project may not work properly until you apply the migrations for app(s): admin, auth, contenttypes, sessions.
Run 'python manage.py migrate' to apply them.
April 13, 2024 - 13:13:55
Django version 4.2.11, using settings 'config.settings'
Starting development server at http://0.0.0.0:8080/
Quit the server with CONTROL-C.

[13/Apr/2024 13:14:04] "GET /pybo HTTP/1.1" 301 0
[13/Apr/2024 13:14:04] "GET /pybo/ HTTP/1.1" 200 53
/root/mysite/config/urls.py changed, reloading.
Watching for file changes with StatReloader
Performing system checks...

System check identified no issues (0 silenced).

You have 18 unapplied migration(s). Your project may not work properly until you apply the migrations for app(s): admin, auth, contenttypes, sessions.
Run 'python manage.py migrate' to apply them.
April 13, 2024 - 13:14:29
Django version 4.2.11, using settings 'config.settings'
Starting development server at http://0.0.0.0:8080/
Quit the server with CONTROL-C.

/root/mysite/config/urls.py changed, reloading.
Watching for file changes with StatReloader
Performing system checks...

System check identified no issues (0 silenced).

You have 18 unapplied migration(s). Your project may not work properly until you apply the migrations for app(s): admin, auth, contenttypes, sessions.
Run 'python manage.py migrate' to apply them.
April 13, 2024 - 13:14:38
Django version 4.2.11, using settings 'config.settings'
Starting development server at http://0.0.0.0:8080/
Quit the server with CONTROL-C.

/root/mysite/config/urls.py changed, reloading.
Watching for file changes with StatReloader
Performing system checks...

Exception in thread django-main-thread:
Traceback (most recent call last):
  File "/usr/lib/python3.8/threading.py", line 932, in _bootstrap_inner
    self.run()
  File "/usr/lib/python3.8/threading.py", line 870, in run
    self._target(*self._args, **self._kwargs)
  File "/usr/local/lib/python3.8/dist-packages/django/utils/autoreload.py", line 64, in wrapper
    fn(*args, **kwargs)
  File "/usr/local/lib/python3.8/dist-packages/django/core/management/commands/runserver.py", line 133, in inner_run
    self.check(display_num_errors=True)
  File "/usr/local/lib/python3.8/dist-packages/django/core/management/base.py", line 485, in check
    all_issues = checks.run_checks(
  File "/usr/local/lib/python3.8/dist-packages/django/core/checks/registry.py", line 88, in run_checks
    new_errors = check(app_configs=app_configs, databases=databases)
  File "/usr/local/lib/python3.8/dist-packages/django/core/checks/urls.py", line 14, in check_url_config
    return check_resolver(resolver)
  File "/usr/local/lib/python3.8/dist-packages/django/core/checks/urls.py", line 24, in check_resolver
    return check_method()
  File "/usr/local/lib/python3.8/dist-packages/django/urls/resolvers.py", line 494, in check
    for pattern in self.url_patterns:
  File "/usr/local/lib/python3.8/dist-packages/django/utils/functional.py", line 57, in __get__
    res = instance.__dict__[self.name] = self.func(instance)
  File "/usr/local/lib/python3.8/dist-packages/django/urls/resolvers.py", line 715, in url_patterns
    patterns = getattr(self.urlconf_module, "urlpatterns", self.urlconf_module)
  File "/usr/local/lib/python3.8/dist-packages/django/utils/functional.py", line 57, in __get__
    res = instance.__dict__[self.name] = self.func(instance)
  File "/usr/local/lib/python3.8/dist-packages/django/urls/resolvers.py", line 708, in urlconf_module
    return import_module(self.urlconf_name)
  File "/usr/lib/python3.8/importlib/__init__.py", line 127, in import_module
    return _bootstrap._gcd_import(name[level:], package, level)
  File "<frozen importlib._bootstrap>", line 1014, in _gcd_import
  File "<frozen importlib._bootstrap>", line 991, in _find_and_load
  File "<frozen importlib._bootstrap>", line 975, in _find_and_load_unlocked
  File "<frozen importlib._bootstrap>", line 671, in _load_unlocked
  File "<frozen importlib._bootstrap_external>", line 783, in exec_module
  File "<frozen importlib._bootstrap>", line 219, in _call_with_frames_removed
  File "/root/mysite/config/urls.py", line 6, in <module>
    path('pybo/', views.index),
NameError: name 'views' is not defined
/root/mysite/config/urls.py changed, reloading.
Watching for file changes with StatReloader
Performing system checks...

Exception in thread django-main-thread:
Traceback (most recent call last):
  File "/usr/lib/python3.8/threading.py", line 932, in _bootstrap_inner
    self.run()
  File "/usr/lib/python3.8/threading.py", line 870, in run
    self._target(*self._args, **self._kwargs)
  File "/usr/local/lib/python3.8/dist-packages/django/utils/autoreload.py", line 64, in wrapper
    fn(*args, **kwargs)
  File "/usr/local/lib/python3.8/dist-packages/django/core/management/commands/runserver.py", line 133, in inner_run
    self.check(display_num_errors=True)
  File "/usr/local/lib/python3.8/dist-packages/django/core/management/base.py", line 485, in check
    all_issues = checks.run_checks(
  File "/usr/local/lib/python3.8/dist-packages/django/core/checks/registry.py", line 88, in run_checks
    new_errors = check(app_configs=app_configs, databases=databases)
  File "/usr/local/lib/python3.8/dist-packages/django/core/checks/urls.py", line 14, in check_url_config
    return check_resolver(resolver)
  File "/usr/local/lib/python3.8/dist-packages/django/core/checks/urls.py", line 24, in check_resolver
    return check_method()
  File "/usr/local/lib/python3.8/dist-packages/django/urls/resolvers.py", line 494, in check
    for pattern in self.url_patterns:
  File "/usr/local/lib/python3.8/dist-packages/django/utils/functional.py", line 57, in __get__
    res = instance.__dict__[self.name] = self.func(instance)
  File "/usr/local/lib/python3.8/dist-packages/django/urls/resolvers.py", line 715, in url_patterns
    patterns = getattr(self.urlconf_module, "urlpatterns", self.urlconf_module)
  File "/usr/local/lib/python3.8/dist-packages/django/utils/functional.py", line 57, in __get__
    res = instance.__dict__[self.name] = self.func(instance)
  File "/usr/local/lib/python3.8/dist-packages/django/urls/resolvers.py", line 708, in urlconf_module
    return import_module(self.urlconf_name)
  File "/usr/lib/python3.8/importlib/__init__.py", line 127, in import_module
    return _bootstrap._gcd_import(name[level:], package, level)
  File "<frozen importlib._bootstrap>", line 1014, in _gcd_import
  File "<frozen importlib._bootstrap>", line 991, in _find_and_load
  File "<frozen importlib._bootstrap>", line 975, in _find_and_load_unlocked
  File "<frozen importlib._bootstrap>", line 671, in _load_unlocked
  File "<frozen importlib._bootstrap_external>", line 783, in exec_module
  File "<frozen importlib._bootstrap>", line 219, in _call_with_frames_removed
  File "/root/mysite/config/urls.py", line 6, in <module>
    path('pybo/', include('pybo.urls')),
  File "/usr/local/lib/python3.8/dist-packages/django/urls/conf.py", line 38, in include
    urlconf_module = import_module(urlconf_module)
  File "/usr/lib/python3.8/importlib/__init__.py", line 127, in import_module
    return _bootstrap._gcd_import(name[level:], package, level)
  File "<frozen importlib._bootstrap>", line 1014, in _gcd_import
  File "<frozen importlib._bootstrap>", line 991, in _find_and_load
  File "<frozen importlib._bootstrap>", line 973, in _find_and_load_unlocked
ModuleNotFoundError: No module named 'pybo.urls'
